{
 "cells": [
  {
   "cell_type": "code",
   "execution_count": 2,
   "metadata": {},
   "outputs": [],
   "source": [
    "import dtale"
   ]
  },
  {
   "cell_type": "code",
   "execution_count": 3,
   "metadata": {
    "scrolled": true
   },
   "outputs": [
    {
     "data": {
      "text/html": [
       "\n",
       "        <iframe\n",
       "            width=\"100%\"\n",
       "            height=\"475\"\n",
       "            src=\"http://EnterX:40000/dtale/iframe/1\"\n",
       "            frameborder=\"0\"\n",
       "            allowfullscreen\n",
       "            \n",
       "        ></iframe>\n",
       "        "
      ],
      "text/plain": [
       "<IPython.lib.display.IFrame at 0x2925060f490>"
      ]
     },
     "metadata": {},
     "output_type": "display_data"
    },
    {
     "data": {
      "text/plain": []
     },
     "execution_count": 3,
     "metadata": {},
     "output_type": "execute_result"
    },
    {
     "name": "stdout",
     "output_type": "stream",
     "text": [
      "       data\n",
      "0         1\n",
      "30199     1\n",
      "30135     1\n",
      "30136     1\n",
      "30137     1\n",
      "...     ...\n",
      "15072     1\n",
      "15073     1\n",
      "15074     1\n",
      "15075     1\n",
      "45210     1\n",
      "\n",
      "[45211 rows x 1 columns]\n",
      "Exception on /dtale/charts/_dash-update-component [POST]\n",
      "Traceback (most recent call last):\n",
      "  File \"C:\\Users\\Moh\\anaconda3\\lib\\site-packages\\flask\\app.py\", line 2525, in wsgi_app\n",
      "    response = self.full_dispatch_request()\n",
      "  File \"C:\\Users\\Moh\\anaconda3\\lib\\site-packages\\flask\\app.py\", line 1822, in full_dispatch_request\n",
      "    rv = self.handle_user_exception(e)\n",
      "  File \"C:\\Users\\Moh\\anaconda3\\lib\\site-packages\\flask\\app.py\", line 1820, in full_dispatch_request\n",
      "    rv = self.dispatch_request()\n",
      "  File \"C:\\Users\\Moh\\anaconda3\\lib\\site-packages\\flask\\app.py\", line 1796, in dispatch_request\n",
      "    return self.ensure_sync(self.view_functions[rule.endpoint])(**view_args)\n",
      "  File \"C:\\Users\\Moh\\anaconda3\\lib\\site-packages\\dash\\dash.py\", line 1274, in dispatch\n",
      "    ctx.run(\n",
      "  File \"C:\\Users\\Moh\\anaconda3\\lib\\site-packages\\dash\\_callback.py\", line 440, in add_context\n",
      "    output_value = func(*func_args, **func_kwargs)  # %% callback invoked %%\n",
      "  File \"C:\\Users\\Moh\\anaconda3\\lib\\site-packages\\dtale\\dash_application\\views.py\", line 1283, in group_values\n",
      "    group_vals = build_group_val_options(group_vals, group_cols)\n",
      "  File \"C:\\Users\\Moh\\anaconda3\\lib\\site-packages\\dtale\\dash_application\\layout\\layout.py\", line 1258, in build_group_val_options\n",
      "    group_vals = find_group_vals(df, group_cols)\n",
      "  File \"C:\\Users\\Moh\\anaconda3\\lib\\site-packages\\dtale\\charts\\utils.py\", line 1015, in find_group_vals\n",
      "    group_vals, _ = retrieve_chart_data(df, group_cols)\n",
      "  File \"C:\\Users\\Moh\\anaconda3\\lib\\site-packages\\dtale\\charts\\utils.py\", line 347, in retrieve_chart_data\n",
      "    all_data = pd.concat(all_data, axis=1)\n",
      "  File \"C:\\Users\\Moh\\anaconda3\\lib\\site-packages\\pandas\\util\\_decorators.py\", line 311, in wrapper\n",
      "    return func(*args, **kwargs)\n",
      "  File \"C:\\Users\\Moh\\anaconda3\\lib\\site-packages\\pandas\\core\\reshape\\concat.py\", line 347, in concat\n",
      "    op = _Concatenator(\n",
      "  File \"C:\\Users\\Moh\\anaconda3\\lib\\site-packages\\pandas\\core\\reshape\\concat.py\", line 404, in __init__\n",
      "    raise ValueError(\"No objects to concatenate\")\n",
      "ValueError: No objects to concatenate\n"
     ]
    },
    {
     "name": "stderr",
     "output_type": "stream",
     "text": [
      "2023-01-27 00:51:23,983 - ERROR    - Exception on /dtale/charts/_dash-update-component [POST]\n",
      "Traceback (most recent call last):\n",
      "  File \"C:\\Users\\Moh\\anaconda3\\lib\\site-packages\\flask\\app.py\", line 2525, in wsgi_app\n",
      "    response = self.full_dispatch_request()\n",
      "  File \"C:\\Users\\Moh\\anaconda3\\lib\\site-packages\\flask\\app.py\", line 1822, in full_dispatch_request\n",
      "    rv = self.handle_user_exception(e)\n",
      "  File \"C:\\Users\\Moh\\anaconda3\\lib\\site-packages\\flask\\app.py\", line 1820, in full_dispatch_request\n",
      "    rv = self.dispatch_request()\n",
      "  File \"C:\\Users\\Moh\\anaconda3\\lib\\site-packages\\flask\\app.py\", line 1796, in dispatch_request\n",
      "    return self.ensure_sync(self.view_functions[rule.endpoint])(**view_args)\n",
      "  File \"C:\\Users\\Moh\\anaconda3\\lib\\site-packages\\dash\\dash.py\", line 1274, in dispatch\n",
      "    ctx.run(\n",
      "  File \"C:\\Users\\Moh\\anaconda3\\lib\\site-packages\\dash\\_callback.py\", line 440, in add_context\n",
      "    output_value = func(*func_args, **func_kwargs)  # %% callback invoked %%\n",
      "  File \"C:\\Users\\Moh\\anaconda3\\lib\\site-packages\\dtale\\dash_application\\views.py\", line 1283, in group_values\n",
      "    group_vals = build_group_val_options(group_vals, group_cols)\n",
      "  File \"C:\\Users\\Moh\\anaconda3\\lib\\site-packages\\dtale\\dash_application\\layout\\layout.py\", line 1258, in build_group_val_options\n",
      "    group_vals = find_group_vals(df, group_cols)\n",
      "  File \"C:\\Users\\Moh\\anaconda3\\lib\\site-packages\\dtale\\charts\\utils.py\", line 1015, in find_group_vals\n",
      "    group_vals, _ = retrieve_chart_data(df, group_cols)\n",
      "  File \"C:\\Users\\Moh\\anaconda3\\lib\\site-packages\\dtale\\charts\\utils.py\", line 347, in retrieve_chart_data\n",
      "    all_data = pd.concat(all_data, axis=1)\n",
      "  File \"C:\\Users\\Moh\\anaconda3\\lib\\site-packages\\pandas\\util\\_decorators.py\", line 311, in wrapper\n",
      "    return func(*args, **kwargs)\n",
      "  File \"C:\\Users\\Moh\\anaconda3\\lib\\site-packages\\pandas\\core\\reshape\\concat.py\", line 347, in concat\n",
      "    op = _Concatenator(\n",
      "  File \"C:\\Users\\Moh\\anaconda3\\lib\\site-packages\\pandas\\core\\reshape\\concat.py\", line 404, in __init__\n",
      "    raise ValueError(\"No objects to concatenate\")\n",
      "ValueError: No objects to concatenate\n"
     ]
    },
    {
     "name": "stdout",
     "output_type": "stream",
     "text": [
      "Executing shutdown due to inactivity...\n"
     ]
    },
    {
     "name": "stderr",
     "output_type": "stream",
     "text": [
      "2023-01-27 01:54:02,414 - INFO     - Executing shutdown due to inactivity...\n"
     ]
    },
    {
     "name": "stdout",
     "output_type": "stream",
     "text": [
      "Executing shutdown...\n"
     ]
    },
    {
     "name": "stderr",
     "output_type": "stream",
     "text": [
      "2023-01-27 01:54:06,583 - INFO     - Executing shutdown...\n"
     ]
    },
    {
     "name": "stdout",
     "output_type": "stream",
     "text": [
      "Exception on /shutdown [GET]\n",
      "Traceback (most recent call last):\n",
      "  File \"C:\\Users\\Moh\\anaconda3\\lib\\site-packages\\flask\\app.py\", line 2525, in wsgi_app\n",
      "    response = self.full_dispatch_request()\n",
      "  File \"C:\\Users\\Moh\\anaconda3\\lib\\site-packages\\flask\\app.py\", line 1822, in full_dispatch_request\n",
      "    rv = self.handle_user_exception(e)\n",
      "  File \"C:\\Users\\Moh\\anaconda3\\lib\\site-packages\\flask\\app.py\", line 1820, in full_dispatch_request\n",
      "    rv = self.dispatch_request()\n",
      "  File \"C:\\Users\\Moh\\anaconda3\\lib\\site-packages\\flask\\app.py\", line 1796, in dispatch_request\n",
      "    return self.ensure_sync(self.view_functions[rule.endpoint])(**view_args)\n",
      "  File \"C:\\Users\\Moh\\anaconda3\\lib\\site-packages\\dtale\\app.py\", line 435, in shutdown\n",
      "    shutdown_server()\n",
      "  File \"C:\\Users\\Moh\\anaconda3\\lib\\site-packages\\dtale\\app.py\", line 421, in shutdown_server\n",
      "    raise RuntimeError(\"Not running with the Werkzeug Server\")\n",
      "RuntimeError: Not running with the Werkzeug Server\n"
     ]
    },
    {
     "name": "stderr",
     "output_type": "stream",
     "text": [
      "2023-01-27 01:54:06,586 - ERROR    - Exception on /shutdown [GET]\n",
      "Traceback (most recent call last):\n",
      "  File \"C:\\Users\\Moh\\anaconda3\\lib\\site-packages\\flask\\app.py\", line 2525, in wsgi_app\n",
      "    response = self.full_dispatch_request()\n",
      "  File \"C:\\Users\\Moh\\anaconda3\\lib\\site-packages\\flask\\app.py\", line 1822, in full_dispatch_request\n",
      "    rv = self.handle_user_exception(e)\n",
      "  File \"C:\\Users\\Moh\\anaconda3\\lib\\site-packages\\flask\\app.py\", line 1820, in full_dispatch_request\n",
      "    rv = self.dispatch_request()\n",
      "  File \"C:\\Users\\Moh\\anaconda3\\lib\\site-packages\\flask\\app.py\", line 1796, in dispatch_request\n",
      "    return self.ensure_sync(self.view_functions[rule.endpoint])(**view_args)\n",
      "  File \"C:\\Users\\Moh\\anaconda3\\lib\\site-packages\\dtale\\app.py\", line 435, in shutdown\n",
      "    shutdown_server()\n",
      "  File \"C:\\Users\\Moh\\anaconda3\\lib\\site-packages\\dtale\\app.py\", line 421, in shutdown_server\n",
      "    raise RuntimeError(\"Not running with the Werkzeug Server\")\n",
      "RuntimeError: Not running with the Werkzeug Server\n"
     ]
    }
   ],
   "source": [
    "import pandas as pd\n",
    "\n",
    "df = pd.read_csv('bankdata.csv')\n",
    "\n",
    "dtale.show(df)"
   ]
  }
 ],
 "metadata": {
  "kernelspec": {
   "display_name": "Python 3 (ipykernel)",
   "language": "python",
   "name": "python3"
  },
  "language_info": {
   "codemirror_mode": {
    "name": "ipython",
    "version": 3
   },
   "file_extension": ".py",
   "mimetype": "text/x-python",
   "name": "python",
   "nbconvert_exporter": "python",
   "pygments_lexer": "ipython3",
   "version": "3.9.12"
  }
 },
 "nbformat": 4,
 "nbformat_minor": 4
}
